<?xml version="1.0" ?>
<robot name="GIC_mirus">
	<link name="base_footprint"/>
	<joint name="base_joint" type="fixed">
		<parent link="base_footprint"/>
		<child link="base_link"/>
		<origin xyz="0 0 0" rpy="0 0 0"/>
	</joint>
	<link name="base_link">
		<visual>
			<origin xyz="0 0 0.0875" rpy="0 0 0"/>
			<geometry>
				<cylinder length="0.15" radius="0.2"/>
			</geometry>
		</visual>
		<collision>
			<origin xyz="0 0 0.0875" rpy="0 0 0"/>
			<geometry>
				<cylinder length="0.15" radius="0.2"/>
			</geometry>
		</collision>
	</link>
	<joint name="wheel_left_joint" type="continuous">
		<parent link="base_link"/>
		<child link="wheel_left_link"/>
		<origin xyz="0.0 0.144 0.023" rpy="-1.57075 0 0"/>
		<axis xyz="0 0 1"/>
	</joint>
	<link name="wheel_left_link">
		<visual>
			<origin xyz="0 0 0" rpy="0 0 0"/>
			<geometry>
				<cylinder length="0.018" radius="0.033"/>
			</geometry>
		</visual>
		<collision>
			<origin xyz="0 0 0" rpy="0 0 0"/>
			<geometry>
				<cylinder length="0.018" radius="0.033"/>
			</geometry>
		</collision>
	</link>
	<joint name="wheel_right_joint" type="continuous">
		<parent link="base_link"/>
		<child link="wheel_right_link"/>
		<origin xyz="0.0 -0.144 0.023" rpy="-1.57075 0 0"/>
		<axis xyz="0 0 1"/>
	</joint>
	<link name="wheel_right_link">
		<visual>
			<origin xyz="0 0 0" rpy="0 0 0"/>
			<geometry>
				<cylinder length="0.018" radius="0.033"/>
			</geometry>
		</visual>
		<collision>
			<origin xyz="0 0 0" rpy="0 0 0"/>
			<geometry>
				<cylinder length="0.018" radius="0.033"/>
			</geometry>
		</collision>
	</link>
	<joint name="caster_back_joint" type="fixed">
		<parent link="base_link"/>
		<child link="caster_back_link"/>
		<origin xyz="-0.144 0 0.015" rpy="0 -1.57075 0"/>
	</joint>
	<link name="caster_back_link">
		<visual>
			<origin xyz="0 0 0" rpy="1.57075 0 0"/>
			<geometry>
				<cylinder length="0.0165" radius="0.025"/>
			</geometry>
		</visual>
		<collision>
			<origin xyz="0 0 0" rpy="1.57075 0 0"/>
			<geometry>
				<cylinder length="0.0165" radius="0.025"/>
			</geometry>
		</collision>
	</link>
	<joint name="caster_front_joint" type="fixed">
		<parent link="base_link"/>
		<child link="caster_front_link"/>
		<origin xyz="0.144 0 0.015" rpy="0 -1.57075 0"/>
	</joint>
	<link name="caster_front_link">
		<visual>
			<origin xyz="0 0 0" rpy="1.57075 0 0"/>
			<geometry>
				<cylinder length="0.0165" radius="0.025"/>
			</geometry>
		</visual>
		<collision>
			<origin xyz="0 0 0" rpy="1.57075 0 0"/>
			<geometry>
				<cylinder length="0.0165" radius="0.025"/>
			</geometry>
		</collision>
	</link>
	<joint name="imu_joint" type="fixed">
		<parent link="base_link"/>
		<child link="imu_link"/>
		<origin xyz="-0.033 -0.02 0.11" rpy="0 0 0"/>
	</joint>
	<link name="imu_link"/>
	<joint name="scan_joint" type="fixed">
		<parent link="base_link"/>
		<child link="base_scan"/>
		<origin xyz="0.1635 0 0.180" rpy="0 0 0"/>
	</joint>
	<link name="base_scan">
		<visual>
			<origin xyz="0 0 0" rpy="0 0 0"/>
			<geometry>
				<cylinder length="0.0225" radius="0.031"/>
			</geometry>
		</visual>
		<collision>
			<origin xyz="0 0 0" rpy="0 0 0"/>
			<geometry>
				<cylinder length="0.0225" radius="0.031"/>
			</geometry>
		</collision>
	</link>
	<joint name="upper_body_joint" type="fixed">
		<parent link="base_link"/>
		<child link="upper_body_link"/>
		<origin xyz="0 0 0.3765" rpy="0 0 0"/>
	</joint>
	<link name="upper_body_link">
		<visual>
			<origin xyz="0 0 0" rpy="0 0 0"/>
			<geometry>
				<cylinder length="0.385" radius="0.2"/>
			</geometry>
		</visual>
		<collision>
			<origin xyz="0 0 0" rpy="0 0 0"/>
			<geometry>
				<cylinder length="0.385" radius="0.2"/>
			</geometry>
		</collision>
	</link>
	<joint name="head_joint" type="prismatic">
		<parent link="base_link"/>
		<child link="head_link" />
		<limit effort="1000.0" lower="0" upper="0.23" velocity="0.05"/>
		<origin xyz="0 0 0.6375" rpy="0 0 0"/>
		<axis xyz="0 0 1"/>
	</joint>
	<link name="head_link">
		<visual>
			<origin xyz="0 0 0" rpy="0 0 0"/>
			<geometry>
				<cylinder length="0.1275" radius="0.2"/>
			</geometry>
		</visual>
		<collision>
			<origin xyz="0 0 0" rpy="0 0 0"/>
			<geometry>
				<cylinder length="0.1275" radius="0.2"/>
			</geometry>
		</collision>
	</link>
	<joint name="camera_rgb_joint" type="prismatic">
		<parent link="base_link"/>
		<child link="camera_rgb_link"/>
		<limit effort="1000.0" lower="0" upper="0.23" velocity="0.05"/>
		<origin xyz="0 0.16 0.62" rpy="0 0 0"/>
		<mimic joint="head_joint" multiplier="1" offset="0" />
		<axis xyz="0 0 1"/>
	</joint>
	<link name="camera_rgb_link">
		<visual>
			<origin xyz="0 0 0" rpy="0 0 0"/>
			<geometry>
				<box size="0.038 0.012 0.038"/>
			</geometry>
		</visual>
	</link>
</robot>